<?xml version="1.0"?>
<robot name="amphibious_vehicle">
    <!-- 材料定义 -->
    <material name="carbon">
        <color rgba="0.2 0.2 0.2 1.0"/>
    </material>
    <material name="white">
        <color rgba="1.0 1.0 1.0 1.0"/>
    </material>
    <material name="red">
        <color rgba="1.0 0.0 0.0 1.0"/>
    </material>
    <material name="rotor">
        <color rgba="0.8 0.8 0.8 1.0"/>
    </material>
    <material name="glass">
        <color rgba="0.2 0.2 0.8 0.3"/>
    </material>

    <!-- 基础坐标系 -->
    <link name="base_link">
        <inertial>
            <origin xyz="0 0 0.2" rpy="0 0 0"/>
            <mass value="100"/>
            <inertia ixx="10" ixy="0" ixz="0" iyy="10" iyz="0" izz="20"/>
        </inertial>
        <visual>
            <origin xyz="0 0 0" rpy="0 0 0"/>
            <geometry>
                <box size="2.5 1.5 0.4"/>
            </geometry>
            <material name="carbon"/>
        </visual>
        <collision>
            <origin xyz="0 0 0" rpy="0 0 0"/>
            <geometry>
                <box size="2.5 1.5 0.4"/>
            </geometry>
        </collision>
    </link>

    <!-- 轿车底盘 -->
    <link name="car_body">
        <inertial>
            <origin xyz="0 0 -0.2" rpy="0 0 0"/>
            <mass value="80"/>
            <inertia ixx="8" ixy="0" ixz="0" iyy="15" iyz="0" izz="12"/>
        </inertial>
        <visual>
            <origin xyz="0 0 -0.2" rpy="0 0 0"/>
            <geometry>
                <box size="2.2 1.2 0.3"/>
            </geometry>
            <material name="white"/>
        </visual>
        <collision>
            <origin xyz="0 0 -0.2" rpy="0 0 0"/>
            <geometry>
                <box size="2.2 1.2 0.3"/>
            </geometry>
        </collision>
    </link>

    <!-- 轿车前盖 -->
    <link name="car_front">
        <inertial>
            <origin xyz="0.8 0 -0.1" rpy="0 0 0"/>
            <mass value="10"/>
            <inertia ixx="0.5" ixy="0" ixz="0" iyy="1" iyz="0" izz="0.8"/>
        </inertial>
        <visual>
            <origin xyz="0.8 0 -0.1" rpy="0 0 0"/>
            <geometry>
                <box size="0.8 1.2 0.2"/>
            </geometry>
            <material name="white"/>
        </visual>
        <collision>
            <origin xyz="0.8 0 -0.1" rpy="0 0 0"/>
            <geometry>
                <box size="0.8 1.2 0.2"/>
            </geometry>
        </collision>
    </link>

    <!-- 轿车后盖 -->
    <link name="car_rear">
        <inertial>
            <origin xyz="-0.8 0 -0.1" rpy="0 0 0"/>
            <mass value="10"/>
            <inertia ixx="0.5" ixy="0" ixz="0" iyy="1" iyz="0" izz="0.8"/>
        </inertial>
        <visual>
            <origin xyz="-0.8 0 -0.1" rpy="0 0 0"/>
            <geometry>
                <box size="0.8 1.2 0.2"/>
            </geometry>
            <material name="white"/>
        </visual>
        <collision>
            <origin xyz="-0.8 0 -0.1" rpy="0 0 0"/>
            <geometry>
                <box size="0.8 1.2 0.2"/>
            </geometry>
        </collision>
    </link>

    <!-- 轿车车顶 -->
    <link name="car_roof">
        <inertial>
            <origin xyz="0 0 0.1" rpy="0 0 0"/>
            <mass value="5"/>
            <inertia ixx="0.3" ixy="0" ixz="0" iyy="0.8" iyz="0" izz="0.5"/>
        </inertial>
        <visual>
            <origin xyz="0 0 0.1" rpy="0 0 0"/>
            <geometry>
                <box size="1.6 1.0 0.1"/>
            </geometry>
            <material name="glass"/>
        </visual>
        <collision>
            <origin xyz="0 0 0.1" rpy="0 0 0"/>
            <geometry>
                <box size="1.6 1.0 0.1"/>
            </geometry>
        </collision>
    </link>

    <!-- 轿车前轮（左） -->
    <link name="front_left_wheel">
        <inertial>
            <origin xyz="0.8 -0.7 -0.3" rpy="0 0 0"/>
            <mass value="5"/>
            <inertia ixx="0.1" ixy="0" ixz="0" iyy="0.2" iyz="0" izz="0.1"/>
        </inertial>
        <visual>
            <origin xyz="0.8 -0.7 -0.3" rpy="0 0 0"/>
            <geometry>
                <cylinder radius="0.2" length="0.15"/>
            </geometry>
            <material name="carbon"/>
        </visual>
        <collision>
            <origin xyz="0.8 -0.7 -0.3" rpy="0 0 0"/>
            <geometry>
                <cylinder radius="0.2" length="0.15"/>
            </geometry>
        </collision>
    </link>

    <!-- 轿车前轮（右） -->
    <link name="front_right_wheel">
        <inertial>
            <origin xyz="0.8 0.7 -0.3" rpy="0 0 0"/>
            <mass value="5"/>
            <inertia ixx="0.1" ixy="0" ixz="0" iyy="0.2" iyz="0" izz="0.1"/>
        </inertial>
        <visual>
            <origin xyz="0.8 0.7 -0.3" rpy="0 0 0"/>
            <geometry>
                <cylinder radius="0.2" length="0.15"/>
            </geometry>
            <material name="carbon"/>
        </visual>
        <collision>
            <origin xyz="0.8 0.7 -0.3" rpy="0 0 0"/>
            <geometry>
                <cylinder radius="0.2" length="0.15"/>
            </geometry>
        </collision>
    </link>

    <!-- 轿车后轮（左） -->
    <link name="rear_left_wheel">
        <inertial>
            <origin xyz="-0.8 -0.7 -0.3" rpy="0 0 0"/>
            <mass value="5"/>
            <inertia ixx="0.1" ixy="0" ixz="0" iyy="0.2" iyz="0" izz="0.1"/>
        </inertial>
        <visual>
            <origin xyz="-0.8 -0.7 -0.3" rpy="0 0 0"/>
            <geometry>
                <cylinder radius="0.2" length="0.15"/>
            </geometry>
            <material name="carbon"/>
        </visual>
        <collision>
            <origin xyz="-0.8 -0.7 -0.3" rpy="0 0 0"/>
            <geometry>
                <cylinder radius="0.2" length="0.15"/>
            </geometry>
        </collision>
    </link>

    <!-- 轿车后轮（右） -->
    <link name="rear_right_wheel">
        <inertial>
            <origin xyz="-0.8 0.7 -0.3" rpy="0 0 0"/>
            <mass value="5"/>
            <inertia ixx="0.1" ixy="0" ixz="0" iyy="0.2" iyz="0" izz="0.1"/>
        </inertial>
        <visual>
            <origin xyz="-0.8 0.7 -0.3" rpy="0 0 0"/>
            <geometry>
                <cylinder radius="0.2" length="0.15"/>
            </geometry>
            <material name="carbon"/>
        </visual>
        <collision>
            <origin xyz="-0.8 0.7 -0.3" rpy="0 0 0"/>
            <geometry>
                <cylinder radius="0.2" length="0.15"/>
            </geometry>
        </collision>
    </link>

    <!-- 四旋翼支架（前左） -->
    <link name="arm_front_left">
        <inertial>
            <origin xyz="0.7 -0.7 0.2" rpy="0 0 0"/>
            <mass value="2"/>
            <inertia ixx="0.05" ixy="0" ixz="0" iyy="0.05" iyz="0" izz="0.01"/>
        </inertial>
        <visual>
            <origin xyz="0.7 -0.7 0.2" rpy="0 0 0"/>
            <geometry>
                <cylinder radius="0.05" length="0.7"/>
            </geometry>
            <material name="carbon"/>
        </visual>
        <collision>
            <origin xyz="0.7 -0.7 0.2" rpy="0 0 0"/>
            <geometry>
                <cylinder radius="0.05" length="0.7"/>
            </geometry>
        </collision>
    </link>

    <!-- 四旋翼支架（前右） -->
    <link name="arm_front_right">
        <inertial>
            <origin xyz="0.7 0.7 0.2" rpy="0 0 0"/>
            <mass value="2"/>
            <inertia ixx="0.05" ixy="0" ixz="0" iyy="0.05" iyz="0" izz="0.01"/>
        </inertial>
        <visual>
            <origin xyz="0.7 0.7 0.2" rpy="0 0 0"/>
            <geometry>
                <cylinder radius="0.05" length="0.7"/>
            </geometry>
            <material name="carbon"/>
        </visual>
        <collision>
            <origin xyz="0.7 0.7 0.2" rpy="0 0 0"/>
            <geometry>
                <cylinder radius="0.05" length="0.7"/>
            </geometry>
        </collision>
    </link>

    <!-- 四旋翼支架（后左） -->
    <link name="arm_rear_left">
        <inertial>
            <origin xyz="-0.7 -0.7 0.2" rpy="0 0 0"/>
            <mass value="2"/>
            <inertia ixx="0.05" ixy="0" ixz="0" iyy="0.05" iyz="0" izz="0.01"/>
        </inertial>
        <visual>
            <origin xyz="-0.7 -0.7 0.2" rpy="0 0 0"/>
            <geometry>
                <cylinder radius="0.05" length="0.7"/>
            </geometry>
            <material name="carbon"/>
        </visual>
        <collision>
            <origin xyz="-0.7 -0.7 0.2" rpy="0 0 0"/>
            <geometry>
                <cylinder radius="0.05" length="0.7"/>
            </geometry>
        </collision>
    </link>

    <!-- 四旋翼支架（后右） -->
    <link name="arm_rear_right">
        <inertial>
            <origin xyz="-0.7 0.7 0.2" rpy="0 0 0"/>
            <mass value="2"/>
            <inertia ixx="0.05" ixy="0" ixz="0" iyy="0.05" iyz="0" izz="0.01"/>
        </inertial>
        <visual>
            <origin xyz="-0.7 0.7 0.2" rpy="0 0 0"/>
            <geometry>
                <cylinder radius="0.05" length="0.7"/>
            </geometry>
            <material name="carbon"/>
        </visual>
        <collision>
            <origin xyz="-0.7 0.7 0.2" rpy="0 0 0"/>
            <geometry>
                <cylinder radius="0.05" length="0.7"/>
            </geometry>
        </collision>
    </link>

    <!-- 四旋翼电机（前左） -->
    <link name="motor_front_left">
        <inertial>
            <origin xyz="1.0 -1.0 0.2" rpy="0 0 0"/>
            <mass value="1"/>
            <inertia ixx="0.01" ixy="0" ixz="0" iyy="0.01" iyz="0" izz="0.005"/>
        </inertial>
        <visual>
            <origin xyz="1.0 -1.0 0.2" rpy="0 0 0"/>
            <geometry>
                <cylinder radius="0.1" length="0.05"/>
            </geometry>
            <material name="red"/>
        </visual>
        <collision>
            <origin xyz="1.0 -1.0 0.2" rpy="0 0 0"/>
            <geometry>
                <cylinder radius="0.1" length="0.05"/>
            </geometry>
        </collision>
    </link>

    <!-- 四旋翼电机（前右） -->
    <link name="motor_front_right">
        <inertial>
            <origin xyz="1.0 1.0 0.2" rpy="0 0 0"/>
            <mass value="1"/>
            <inertia ixx="0.01" ixy="0" ixz="0" iyy="0.01" iyz="0" izz="0.005"/>
        </inertial>
        <visual>
            <origin xyz="1.0 1.0 0.2" rpy="0 0 0"/>
            <geometry>
                <cylinder radius="0.1" length="0.05"/>
            </geometry>
            <material name="red"/>
        </visual>
        <collision>
            <origin xyz="1.0 1.0 0.2" rpy="0 0 0"/>
            <geometry>
                <cylinder radius="0.1" length="0.05"/>
            </geometry>
        </collision>
    </link>

    <!-- 四旋翼电机（后左） -->
    <link name="motor_rear_left">
        <inertial>
            <origin xyz="-1.0 -1.0 0.2" rpy="0 0 0"/>
            <mass value="1"/>
            <inertia ixx="0.01" ixy="0" ixz="0" iyy="0.01" iyz="0" izz="0.005"/>
        </inertial>
        <visual>
            <origin xyz="-1.0 -1.0 0.2" rpy="0 0 0"/>
            <geometry>
                <cylinder radius="0.1" length="0.05"/>
            </geometry>
            <material name="red"/>
        </visual>
        <collision>
            <origin xyz="-1.0 -1.0 0.2" rpy="0 0 0"/>
            <geometry>
                <cylinder radius="0.1" length="0.05"/>
            </geometry>
        </collision>
    </link>

    <!-- 四旋翼电机（后右） -->
    <link name="motor_rear_right">
        <inertial>
            <origin xyz="-1.0 1.0 0.2" rpy="0 0 0"/>
            <mass value="1"/>
            <inertia ixx="0.01" ixy="0" ixz="0" iyy="0.01" iyz="0" izz="0.005"/>
        </inertial>
        <visual>
            <origin xyz="-1.0 1.0 0.2" rpy="0 0 0"/>
            <geometry>
                <cylinder radius="0.1" length="0.05"/>
            </geometry>
            <material name="red"/>
        </visual>
        <collision>
            <origin xyz="-1.0 1.0 0.2" rpy="0 0 0"/>
            <geometry>
                <cylinder radius="0.1" length="0.05"/>
            </geometry>
        </collision>
    </link>

    <!-- 四旋翼螺旋桨（前左） -->
    <link name="rotor_front_left">
        <inertial>
            <origin xyz="1.0 -1.0 0.25" rpy="0 0 0"/>
            <mass value="0.2"/>
            <inertia ixx="0.001" ixy="0" ixz="0" iyy="0.001" iyz="0" izz="0.0005"/>
        </inertial>
        <visual>
            <origin xyz="1.0 -1.0 0.25" rpy="0 0 0"/>
            <geometry>
                <box size="0.8 0.1 0.02"/>
            </geometry>
            <material name="rotor"/>
        </visual>
        <collision>
            <origin xyz="1.0 -1.0 0.25" rpy="0 0 0"/>
            <geometry>
                <box size="0.8 0.1 0.02"/>
            </geometry>
        </collision>
    </link>

    <!-- 四旋翼螺旋桨（前右） -->
    <link name="rotor_front_right">
        <inertial>
            <origin xyz="1.0 1.0 0.25" rpy="0 0 0"/>
            <mass value="0.2"/>
            <inertia ixx="0.001" ixy="0" ixz="0" iyy="0.001" iyz="0" izz="0.0005"/>
        </inertial>
        <visual>
            <origin xyz="1.0 1.0 0.25" rpy="0 0 0"/>
            <geometry>
                <box size="0.8 0.1 0.02"/>
            </geometry>
            <material name="rotor"/>
        </visual>
        <collision>
            <origin xyz="1.0 1.0 0.25" rpy="0 0 0"/>
            <geometry>
                <box size="0.8 0.1 0.02"/>
            </geometry>
        </collision>
    </link>

    <!-- 四旋翼螺旋桨（后左） -->
    <link name="rotor_rear_left">
        <inertial>
            <origin xyz="-1.0 -1.0 0.25" rpy="0 0 0"/>
            <mass value="0.2"/>
            <inertia ixx="0.001" ixy="0" ixz="0" iyy="0.001" iyz="0" izz="0.0005"/>
        </inertial>
        <visual>
            <origin xyz="-1.0 -1.0 0.25" rpy="0 0 0"/>
            <geometry>
                <box size="0.8 0.1 0.02"/>
            </geometry>
            <material name="rotor"/>
        </visual>
        <collision>
            <origin xyz="-1.0 -1.0 0.25" rpy="0 0 0"/>
            <geometry>
                <box size="0.8 0.1 0.02"/>
            </geometry>
        </collision>
    </link>

    <!-- 四旋翼螺旋桨（后右） -->
    <link name="rotor_rear_right">
        <inertial>
            <origin xyz="-1.0 1.0 0.25" rpy="0 0 0"/>
            <mass value="0.2"/>
            <inertia ixx="0.001" ixy="0" ixz="0" iyy="0.001" iyz="0" izz="0.0005"/>
        </inertial>
        <visual>
            <origin xyz="-1.0 1.0 0.25" rpy="0 0 0"/>
            <geometry>
                <box size="0.8 0.1 0.02"/>
            </geometry>
            <material name="rotor"/>
        </visual>
        <collision>
            <origin xyz="-1.0 1.0 0.25" rpy="0 0 0"/>
            <geometry>
                <box size="0.8 0.1 0.02"/>
            </geometry>
        </collision>
    </link>

    <!-- 关节连接定义 -->
    <!-- 底盘连接 -->
    <joint name="car_body_joint" type="fixed">
        <parent link="base_link"/>
        <child link="car_body"/>
        <origin xyz="0 0 -0.2" rpy="0 0 0"/>
    </joint>

    <joint name="car_front_joint" type="fixed">
        <parent link="car_body"/>
        <child link="car_front"/>
        <origin xyz="0.8 0 0" rpy="0 0 0"/>
    </joint>

    <joint name="car_rear_joint" type="fixed">
        <parent link="car_body"/>
        <child link="car_rear"/>
        <origin xyz="-0.8 0 0" rpy="0 0 0"/>
    </joint>

    <joint name="car_roof_joint" type="fixed">
        <parent link="car_body"/>
        <child link="car_roof"/>
        <origin xyz="0 0 0.25" rpy="0 0 0"/>
    </joint>

    <!-- 车轮连接（连续关节，可旋转） -->
    <joint name="front_left_wheel_joint" type="continuous">
        <parent link="car_body"/>
        <child link="front_left_wheel"/>
        <origin xyz="0.8 -0.7 -0.3" rpy="1.5708 0 0"/>
        <axis xyz="0 1 0"/>
    </joint>

    <joint name="front_right_wheel_joint" type="continuous">
        <parent link="car_body"/>
        <child link="front_right_wheel"/>
        <origin xyz="0.8 0.7 -0.3" rpy="1.5708 0 0"/>
        <axis xyz="0 1 0"/>
    </joint>

    <joint name="rear_left_wheel_joint" type="continuous">
        <parent link="car_body"/>
        <child link="rear_left_wheel"/>
        <origin xyz="-0.8 -0.7 -0.3" rpy="1.5708 0 0"/>
        <axis xyz="0 1 0"/>
    </joint>

    <joint name="rear_right_wheel_joint" type="continuous">
        <parent link="car_body"/>
        <child link="rear_right_wheel"/>
        <origin xyz="-0.8 0.7 -0.3" rpy="1.5708 0 0"/>
        <axis xyz="0 1 0"/>
    </joint>

    <!-- 四旋翼支架连接 -->
    <joint name="arm_front_left_joint" type="fixed">
        <parent link="base_link"/>
        <child link="arm_front_left"/>
        <origin xyz="0.35 -0.35 0.2" rpy="0 0 0.7854"/>
    </joint>

    <joint name="arm_front_right_joint" type="fixed">
        <parent link="base_link"/>
        <child link="arm_front_right"/>
        <origin xyz="0.35 0.35 0.2" rpy="0 0 -0.7854"/>
    </joint>

    <joint name="arm_rear_left_joint" type="fixed">
        <parent link="base_link"/>
        <child link="arm_rear_left"/>
        <origin xyz="-0.35 -0.35 0.2" rpy="0 0 -0.7854"/>
    </joint>

    <joint name="arm_rear_right_joint" type="fixed">
        <parent link="base_link"/>
        <child link="arm_rear_right"/>
        <origin xyz="-0.35 0.35 0.2" rpy="0 0 0.7854"/>
    </joint>

    <!-- 电机连接 -->
    <joint name="motor_front_left_joint" type="fixed">
        <parent link="arm_front_left"/>
        <child link="motor_front_left"/>
        <origin xyz="0.35 -0.35 0" rpy="0 0 0"/>
    </joint>

    <joint name="motor_front_right_joint" type="fixed">
        <parent link="arm_front_right"/>
        <child link="motor_front_right"/>
        <origin xyz="0.35 0.35 0" rpy="0 0 0"/>
    </joint>

    <joint name="motor_rear_left_joint" type="fixed">
        <parent link="arm_rear_left"/>
        <child link="motor_rear_left"/>
        <origin xyz="-0.35 -0.35 0" rpy="0 0 0"/>
    </joint>

    <joint name="motor_rear_right_joint" type="fixed">
        <parent link="arm_rear_right"/>
        <child link="motor_rear_right"/>
        <origin xyz="-0.35 0.35 0" rpy="0 0 0"/>
    </joint>

    <!-- 螺旋桨连接（连续关节，可旋转） -->
    <joint name="rotor_front_left_joint" type="continuous">
        <parent link="motor_front_left"/>
        <child link="rotor_front_left"/>
        <origin xyz="0 0 0.05" rpy="0 0 0"/>
        <axis xyz="0 0 1"/>
    </joint>

    <joint name="rotor_front_right_joint" type="continuous">
        <parent link="motor_front_right"/>
        <child link="rotor_front_right"/>
        <origin xyz="0 0 0.05" rpy="0 0 0"/>
        <axis xyz="0 0 1"/>
    </joint>

    <joint name="rotor_rear_left_joint" type="continuous">
        <parent link="motor_rear_left"/>
        <child link="rotor_rear_left"/>
        <origin xyz="0 0 0.05" rpy="0 0 0"/>
        <axis xyz="0 0 1"/>
    </joint>

    <joint name="rotor_rear_right_joint" type="continuous">
        <parent link="motor_rear_right"/>
        <child link="rotor_rear_right"/>
        <origin xyz="0 0 0.05" rpy="0 0 0"/>
        <axis xyz="0 0 1"/>
    </joint>

    <!-- 定义传动装置（用于控制车轮和螺旋桨） -->
    <transmission name="front_left_wheel_trans">
        <type>transmission_interface/SimpleTransmission</type>
        <joint name="front_left_wheel_joint">
            <hardwareInterface>hardware_interface/VelocityJointInterface</hardwareInterface>
        </joint>
        <actuator name="front_left_wheel_motor">
            <hardwareInterface>hardware_interface/VelocityJointInterface</hardwareInterface>
            <mechanicalReduction>1</mechanicalReduction>
        </actuator>
    </transmission>

    <transmission name="front_right_wheel_trans">
        <type>transmission_interface/SimpleTransmission</type>
        <joint name="front_right_wheel_joint">
            <hardwareInterface>hardware_interface/VelocityJointInterface</hardwareInterface>
        </joint>
        <actuator name="front_right_wheel_motor">
            <hardwareInterface>hardware_interface/VelocityJointInterface</hardwareInterface>
            <mechanicalReduction>1</mechanicalReduction>
        </actuator>
    </transmission>

    <transmission name="rear_left_wheel_trans">
        <type>transmission_interface/SimpleTransmission</type>
        <joint name="rear_left_wheel_joint">
            <hardwareInterface>hardware_interface/VelocityJointInterface</hardwareInterface>
        </joint>
        <actuator name="rear_left_wheel_motor">
            <hardwareInterface>hardware_interface/VelocityJointInterface</hardwareInterface>
            <mechanicalReduction>1</mechanicalReduction>
        </actuator>
    </transmission>

    <transmission name="rear_right_wheel_trans">
        <type>transmission_interface/SimpleTransmission</type>
        <joint name="rear_right_wheel_joint">
            <hardwareInterface>hardware_interface/VelocityJointInterface</hardwareInterface>
        </joint>
        <actuator name="rear_right_wheel_motor">
            <hardwareInterface>hardware_interface/VelocityJointInterface</hardwareInterface>
            <mechanicalReduction>1</mechanicalReduction>
        </actuator>
    </transmission>

    <transmission name="rotor_front_left_trans">
        <type>transmission_interface/SimpleTransmission</type>
        <joint name="rotor_front_left_joint">
            <hardwareInterface>hardware_interface/VelocityJointInterface</hardwareInterface>
        </joint>
        <actuator name="rotor_front_left_motor">
            <hardwareInterface>hardware_interface/VelocityJointInterface</hardwareInterface>
            <mechanicalReduction>1</mechanicalReduction>
        </actuator>
    </transmission>

    <transmission name="rotor_front_right_trans">
        <type>transmission_interface/SimpleTransmission</type>
        <joint name="rotor_front_right_joint">
            <hardwareInterface>hardware_interface/VelocityJointInterface</hardwareInterface>
        </joint>
        <actuator name="rotor_front_right_motor">
            <hardwareInterface>hardware_interface/VelocityJointInterface</hardwareInterface>
            <mechanicalReduction>1</mechanicalReduction>
        </actuator>
    </transmission>

    <transmission name="rotor_rear_left_trans">
        <type>transmission_interface/SimpleTransmission</type>
        <joint name="rotor_rear_left_joint">
            <hardwareInterface>hardware_interface/VelocityJointInterface</hardwareInterface>
        </joint>
        <actuator name="rotor_rear_left_motor">
            <hardwareInterface>hardware_interface/VelocityJointInterface</hardwareInterface>
            <mechanicalReduction>1</mechanicalReduction>
        </actuator>
    </transmission>

    <transmission name="rotor_rear_right_trans">
        <type>transmission_interface/SimpleTransmission</type>
        <joint name="rotor_rear_right_joint">
            <hardwareInterface>hardware_interface/VelocityJointInterface</hardwareInterface>
        </joint>
        <actuator name="rotor_rear_right_motor">
            <hardwareInterface>hardware_interface/VelocityJointInterface</hardwareInterface>
            <mechanicalReduction>1</mechanicalReduction>
        </actuator>
    </transmission>
</robot>    